{"uuid": "3b33bea3-8014-4285-9447-2f99866a51aa", "children": ["c5689e96-4241-462c-9a9c-6be9e5bf1b4e", "24c540b1-2e92-46f5-b6de-ebbf93c77aa1", "7c5d86ea-67f5-425e-8ca8-af78fa20c092", "a1bcfda6-abc9-47ff-81d7-6f2594e89f8c"], "befores": [{"name": "init_driver", "status": "passed", "start": 1657674996678, "stop": 1657675001423}], "afters": [{"name": "init_driver::0", "status": "broken", "statusDetails": {"message": "urllib3.exceptions.MaxRetryError: HTTPConnectionPool(host='localhost', port=65440): Max retries exceeded with url: /session/48e4e55542d2a767b39aa3b01ca32873/window (Caused by NewConnectionError('<urllib3.connection.HTTPConnection object at 0x106c66050>: Failed to establish a new connection: [Errno 61] Connection refused'))\n", "trace": "  File \"/Library/Frameworks/Python.framework/Versions/3.10/lib/python3.10/site-packages/allure_commons/_allure.py\", line 200, in __call__\n    return self._fixture_function(*args, **kwargs)\n  File \"/Library/Frameworks/Python.framework/Versions/3.10/lib/python3.10/site-packages/_pytest/fixtures.py\", line 899, in _teardown_yield_fixture\n    next(it)\n  File \"/Users/svc/PycharmProjects/SeleniumPythonProject/Framework/tests/conftest.py\", line 36, in init_driver\n    driver.close()\n  File \"/Library/Frameworks/Python.framework/Versions/3.10/lib/python3.10/site-packages/selenium/webdriver/remote/webdriver.py\", line 552, in close\n    self.execute(Command.CLOSE)\n  File \"/Library/Frameworks/Python.framework/Versions/3.10/lib/python3.10/site-packages/selenium/webdriver/remote/webdriver.py\", line 433, in execute\n    response = self.command_executor.execute(driver_command, params)\n  File \"/Library/Frameworks/Python.framework/Versions/3.10/lib/python3.10/site-packages/selenium/webdriver/remote/remote_connection.py\", line 344, in execute\n    return self._request(command_info[0], url, body=data)\n  File \"/Library/Frameworks/Python.framework/Versions/3.10/lib/python3.10/site-packages/selenium/webdriver/remote/remote_connection.py\", line 366, in _request\n    response = self._conn.request(method, url, body=body, headers=headers)\n  File \"/Library/Frameworks/Python.framework/Versions/3.10/lib/python3.10/site-packages/urllib3/request.py\", line 74, in request\n    return self.request_encode_url(\n  File \"/Library/Frameworks/Python.framework/Versions/3.10/lib/python3.10/site-packages/urllib3/request.py\", line 96, in request_encode_url\n    return self.urlopen(method, url, **extra_kw)\n  File \"/Library/Frameworks/Python.framework/Versions/3.10/lib/python3.10/site-packages/urllib3/poolmanager.py\", line 376, in urlopen\n    response = conn.urlopen(method, u.request_uri, **kw)\n  File \"/Library/Frameworks/Python.framework/Versions/3.10/lib/python3.10/site-packages/urllib3/connectionpool.py\", line 815, in urlopen\n    return self.urlopen(\n  File \"/Library/Frameworks/Python.framework/Versions/3.10/lib/python3.10/site-packages/urllib3/connectionpool.py\", line 815, in urlopen\n    return self.urlopen(\n  File \"/Library/Frameworks/Python.framework/Versions/3.10/lib/python3.10/site-packages/urllib3/connectionpool.py\", line 815, in urlopen\n    return self.urlopen(\n  File \"/Library/Frameworks/Python.framework/Versions/3.10/lib/python3.10/site-packages/urllib3/connectionpool.py\", line 787, in urlopen\n    retries = retries.increment(\n  File \"/Library/Frameworks/Python.framework/Versions/3.10/lib/python3.10/site-packages/urllib3/util/retry.py\", line 592, in increment\n    raise MaxRetryError(_pool, url, error or ResponseError(cause))\n"}, "start": 1657675043483, "stop": 1657675043487}], "start": 1657674996677, "stop": 1657675043487}