{"uuid": "188ed9de-1eee-4128-add2-e12492df266f", "children": ["1fa2e437-9543-4267-aeab-51d95078e15e", "8faddddf-38c9-4c29-998b-c41660d2af7d", "d5ecd597-b7fa-4265-a3f2-1e19c74e64ae", "8a09bcea-32fd-4141-bbee-6b9bdaf97274"], "befores": [{"name": "init_driver", "status": "passed", "start": 1657674996675, "stop": 1657675002412}], "afters": [{"name": "init_driver::0", "status": "broken", "statusDetails": {"message": "urllib3.exceptions.MaxRetryError: HTTPConnectionPool(host='localhost', port=65458): Max retries exceeded with url: /session/fe84174e064faf55be520d2d2857e005/window (Caused by NewConnectionError('<urllib3.connection.HTTPConnection object at 0x1051d3490>: Failed to establish a new connection: [Errno 61] Connection refused'))\n", "trace": "  File \"/Library/Frameworks/Python.framework/Versions/3.10/lib/python3.10/site-packages/allure_commons/_allure.py\", line 200, in __call__\n    return self._fixture_function(*args, **kwargs)\n  File \"/Library/Frameworks/Python.framework/Versions/3.10/lib/python3.10/site-packages/_pytest/fixtures.py\", line 899, in _teardown_yield_fixture\n    next(it)\n  File \"/Users/svc/PycharmProjects/SeleniumPythonProject/Framework/tests/conftest.py\", line 36, in init_driver\n    driver.close()\n  File \"/Library/Frameworks/Python.framework/Versions/3.10/lib/python3.10/site-packages/selenium/webdriver/remote/webdriver.py\", line 552, in close\n    self.execute(Command.CLOSE)\n  File \"/Library/Frameworks/Python.framework/Versions/3.10/lib/python3.10/site-packages/selenium/webdriver/remote/webdriver.py\", line 433, in execute\n    response = self.command_executor.execute(driver_command, params)\n  File \"/Library/Frameworks/Python.framework/Versions/3.10/lib/python3.10/site-packages/selenium/webdriver/remote/remote_connection.py\", line 344, in execute\n    return self._request(command_info[0], url, body=data)\n  File \"/Library/Frameworks/Python.framework/Versions/3.10/lib/python3.10/site-packages/selenium/webdriver/remote/remote_connection.py\", line 366, in _request\n    response = self._conn.request(method, url, body=body, headers=headers)\n  File \"/Library/Frameworks/Python.framework/Versions/3.10/lib/python3.10/site-packages/urllib3/request.py\", line 74, in request\n    return self.request_encode_url(\n  File \"/Library/Frameworks/Python.framework/Versions/3.10/lib/python3.10/site-packages/urllib3/request.py\", line 96, in request_encode_url\n    return self.urlopen(method, url, **extra_kw)\n  File \"/Library/Frameworks/Python.framework/Versions/3.10/lib/python3.10/site-packages/urllib3/poolmanager.py\", line 376, in urlopen\n    response = conn.urlopen(method, u.request_uri, **kw)\n  File \"/Library/Frameworks/Python.framework/Versions/3.10/lib/python3.10/site-packages/urllib3/connectionpool.py\", line 815, in urlopen\n    return self.urlopen(\n  File \"/Library/Frameworks/Python.framework/Versions/3.10/lib/python3.10/site-packages/urllib3/connectionpool.py\", line 815, in urlopen\n    return self.urlopen(\n  File \"/Library/Frameworks/Python.framework/Versions/3.10/lib/python3.10/site-packages/urllib3/connectionpool.py\", line 815, in urlopen\n    return self.urlopen(\n  File \"/Library/Frameworks/Python.framework/Versions/3.10/lib/python3.10/site-packages/urllib3/connectionpool.py\", line 787, in urlopen\n    retries = retries.increment(\n  File \"/Library/Frameworks/Python.framework/Versions/3.10/lib/python3.10/site-packages/urllib3/util/retry.py\", line 592, in increment\n    raise MaxRetryError(_pool, url, error or ResponseError(cause))\n"}, "start": 1657675043408, "stop": 1657675043414}], "start": 1657674996675, "stop": 1657675043414}